<robot
  name="exo2">
  <link
    name="pelvis_link">
    <inertial>
      <origin
        xyz="-0.0229570391634381 9.79841631494616E-06 -0.0791579286364338"
        rpy="0 0 0" />
      <mass
        value="0.876180506785054" />
      <inertia
        ixx="0.0018274599707449"
        ixy="2.77946712790357E-06"
        ixz="-2.82148369387848E-05"
        iyy="0.000542716087592878"
        iyz="-1.88988098707461E-06"
        izz="0.00181893616699862" />
    </inertial>
    <visual>
      <origin
        xyz="0 0 0"
        rpy="0 0 0" />
      <geometry>
        <mesh
          filename="package://exo2/meshes/pelvis_link.STL" />
      </geometry>
      <material
        name="">
        <color
          rgba="0.792156862745098 0.819607843137255 0.933333333333333 1" />
      </material>
    </visual>
    <collision>
      <origin
        xyz="0 0 0"
        rpy="0 0 0" />
      <geometry>
        <mesh
          filename="package://exo2/meshes/pelvis_link.STL" />
      </geometry>
    </collision>
  </link>
  <link
    name="l_leg_hip_y_link">
    <inertial>
      <origin
        xyz="0.000194867122171649 3.9899573725577E-05 0.00285846708477097"
        rpy="0 0 0" />
      <mass
        value="0.0865282073086405" />
      <inertia
        ixx="1.13911348666239E-06"
        ixy="-1.11411307071077E-10"
        ixz="-2.37227170803843E-08"
        iyy="6.28995782612359E-06"
        iyz="-4.85729089952576E-09"
        izz="5.15088996299801E-06" />
    </inertial>
    <visual>
      <origin
        xyz="0 0 0"
        rpy="0 0 0" />
      <geometry>
        <mesh
          filename="package://exo2/meshes/l_leg_hip_y_link.STL" />
      </geometry>
      <material
        name="">
        <color
          rgba="0.792156862745098 0.819607843137255 0.933333333333333 1" />
      </material>
    </visual>
    <collision>
      <origin
        xyz="0 0 0"
        rpy="0 0 0" />
      <geometry>
        <mesh
          filename="package://exo2/meshes/l_leg_hip_y_link.STL" />
      </geometry>
    </collision>
  </link>
  <joint
    name="l_leg_hip_y"
    type="revolute">
    <origin
      xyz="0.023 0.125 -0.0813"
      rpy="0 0 0" />
    <parent
      link="pelvis_link" />
    <child
      link="l_leg_hip_y_link" />
    <axis
      xyz="0 0 1" />
    <limit
      effort="0"
      velocity="0" />
    <dynamics
      damping="0.1" />
  </joint>
  <link
    name="l_leg_hip_r_link">
    <inertial>
      <origin
        xyz="-0.0228672098615241 0.026657202473467 -0.0578970138026583"
        rpy="0 0 0" />
      <mass
        value="0.57732261179279" />
      <inertia
        ixx="0.0018145712595036"
        ixy="-1.42788361438729E-05"
        ixz="-0.000341806477751158"
        iyy="0.00199151436868998"
        iyz="-4.24239917577191E-06"
        izz="0.000385603527413131" />
    </inertial>
    <visual>
      <origin
        xyz="0 0 0"
        rpy="0 0 0" />
      <geometry>
        <mesh
          filename="package://exo2/meshes/l_leg_hip_r_link.STL" />
      </geometry>
      <material
        name="">
        <color
          rgba="0.792156862745098 0.819607843137255 0.933333333333333 1" />
      </material>
    </visual>
    <collision>
      <origin
        xyz="0 0 0"
        rpy="0 0 0" />
      <geometry>
        <mesh
          filename="package://exo2/meshes/l_leg_hip_r_link.STL" />
      </geometry>
    </collision>
  </link>
  <joint
    name="l_leg_hip_r"
    type="revolute">
    <origin
      xyz="0 0 0"
      rpy="0 0 0" />
    <parent
      link="l_leg_hip_y_link" />
    <child
      link="l_leg_hip_r_link" />
    <axis
      xyz="1 0 0" />
    <limit
      effort="0"
      velocity="0" />
  </joint>
  <link
    name="l_leg_hip_p_link">
    <inertial>
      <origin
        xyz="0.03268 0.0184 -0.15583"
        rpy="0 0 0" />
      <mass
        value="0.28668" />
      <inertia
        ixx="0.0010977"
        ixy="-4.3367E-05"
        ixz="0.00021162"
        iyy="0.0010532"
        iyz="0.0002017"
        izz="0.00013617" />
    </inertial>
    <visual>
      <origin
        xyz="0 0 0"
        rpy="0 0 0" />
      <geometry>
        <mesh
          filename="package://exo2/meshes/l_leg_hip_p_link.STL" />
      </geometry>
      <material
        name="">
        <color
          rgba="0.79216 0.81961 0.93333 1" />
      </material>
    </visual>
    <collision>
      <origin
        xyz="0 0 0"
        rpy="0 0 0" />
      <geometry>
        <mesh
          filename="package://exo2/meshes/l_leg_hip_p_link.STL" />
      </geometry>
    </collision>
  </link>
  <joint
    name="l_leg_hip_p"
    type="revolute">
    <origin
      xyz="0.000765 -0.00018721 -0.14104"
      rpy="0 0 0" />
    <parent
      link="l_leg_hip_r_link" />
    <child
      link="l_leg_hip_p_link" />
    <axis
      xyz="0 1 0" />
    <limit
      effort="0"
      velocity="0" />
  </joint>
  <link
    name="l_leg_kn_p_link">
    <inertial>
      <origin
        xyz="-0.0371195392851587 -0.0290806755044972 -0.127161963516106"
        rpy="0 0 0" />
      <mass
        value="0.501847197637487" />
      <inertia
        ixx="0.000743351806811496"
        ixy="-5.28895214340804E-05"
        ixz="-4.63291190421771E-05"
        iyy="0.00096853459109235"
        iyz="-0.000141414322901002"
        izz="0.00058448391041593" />
    </inertial>
    <visual>
      <origin
        xyz="0 0 0"
        rpy="0 0 0" />
      <geometry>
        <mesh
          filename="package://exo2/meshes/l_leg_kn_p_link.STL" />
      </geometry>
      <material
        name="">
        <color
          rgba="0.792156862745098 0.819607843137255 0.933333333333333 1" />
      </material>
    </visual>
    <collision>
      <origin
        xyz="0 0 0"
        rpy="0 0 0" />
      <geometry>
        <mesh
          filename="package://exo2/meshes/l_leg_kn_p_link.STL" />
      </geometry>
    </collision>
  </link>
  <joint
    name="l_leg_kn_p"
    type="revolute">
    <origin
      xyz="0.050381 -0.00051236 -0.23986"
      rpy="0 0 0" />
    <parent
      link="l_leg_hip_p_link" />
    <child
      link="l_leg_kn_p_link" />
    <axis
      xyz="0 1 0" />
    <limit
      effort="0"
      velocity="0" />
  </joint>
  <link
    name="l_leg_an_p_link">
    <inertial>
      <origin
        xyz="0.029948 -0.00049014 -0.031986"
        rpy="0 0 0" />
      <mass
        value="0.032575" />
      <inertia
        ixx="4.1828E-06"
        ixy="4.3165E-08"
        ixz="-1.5865E-12"
        iyy="6.8195E-06"
        iyz="2.5966E-14"
        izz="2.6382E-06" />
    </inertial>
    <visual>
      <origin
        xyz="0 0 0"
        rpy="0 0 0" />
      <geometry>
        <mesh
          filename="package://exo2/meshes/l_leg_an_p_link.STL" />
      </geometry>
      <material
        name="">
        <color
          rgba="0.79216 0.81961 0.93333 1" />
      </material>
    </visual>
    <collision>
      <origin
        xyz="0 0 0"
        rpy="0 0 0" />
      <geometry>
        <mesh
          filename="package://exo2/meshes/l_leg_an_p_link.STL" />
      </geometry>
    </collision>
  </link>
  <joint
    name="l_leg_an_p"
    type="revolute">
    <origin
      xyz="-0.0035327 -0.00026509 -0.20997"
      rpy="0 0 0" />
    <parent
      link="l_leg_kn_p_link" />
    <child
      link="l_leg_an_p_link" />
    <axis
      xyz="0 0 1" />
    <limit
      effort="0"
      velocity="0" />
  </joint>
  <link
    name="l_leg_an_r_link">
    <inertial>
      <origin
        xyz="-0.036963 -0.04546 -0.032546"
        rpy="0 0 0" />
      <mass
        value="0.20448" />
      <inertia
        ixx="2.9051E-05"
        ixy="-6.5131E-06"
        ixz="-2.3906E-06"
        iyy="7.4234E-05"
        iyz="-9.8229E-08"
        izz="7.3588E-05" />
    </inertial>
    <visual>
      <origin
        xyz="0 0 0"
        rpy="0 0 0" />
      <geometry>
        <mesh
          filename="package://exo2/meshes/l_leg_an_r_link.STL" />
      </geometry>
      <material
        name="">
        <color
          rgba="0.79216 0.81961 0.93333 1" />
      </material>
    </visual>
    <collision>
      <origin
        xyz="0 0 0"
        rpy="0 0 0" />
      <geometry>
        <mesh
          filename="package://exo2/meshes/l_leg_an_r_link.STL" />
      </geometry>
    </collision>
  </link>
  <joint
    name="l_leg_an_r"
    type="revolute">
    <origin
      xyz="0 0 0"
      rpy="0 0 0" />
    <parent
      link="l_leg_an_p_link" />
    <child
      link="l_leg_an_r_link" />
    <axis
      xyz="-1 0 0" />
    <limit
      effort="0"
      velocity="0" />
  </joint>
  <link
    name="r_leg_hip_y_link">
    <inertial>
      <origin
        xyz="0.000194859023416288 -3.99011003911834E-05 0.0028585007264543"
        rpy="0 0 0" />
      <mass
        value="0.0865285747250378" />
      <inertia
        ixx="1.13912095207425E-06"
        ixy="1.11410861161273E-10"
        ixz="-2.37218084077287E-08"
        iyy="6.28996524419591E-06"
        iyz="4.85749257153188E-09"
        izz="5.15088991911781E-06" />
    </inertial>
    <visual>
      <origin
        xyz="0 0 0"
        rpy="0 0 0" />
      <geometry>
        <mesh
          filename="package://exo2/meshes/r_leg_hip_y_link.STL" />
      </geometry>
      <material
        name="">
        <color
          rgba="0.792156862745098 0.819607843137255 0.933333333333333 1" />
      </material>
    </visual>
    <collision>
      <origin
        xyz="0 0 0"
        rpy="0 0 0" />
      <geometry>
        <mesh
          filename="package://exo2/meshes/r_leg_hip_y_link.STL" />
      </geometry>
    </collision>
  </link>
  <joint
    name="r_leg_hip_y"
    type="revolute">
    <origin
      xyz="0.023 -0.125 -0.0813"
      rpy="0 0 0" />
    <parent
      link="pelvis_link" />
    <child
      link="r_leg_hip_y_link" />
    <axis
      xyz="0 0 1" />
    <limit
      effort="0"
      velocity="0" />
  </joint>
  <link
    name="r_leg_hip_r_link">
    <inertial>
      <origin
        xyz="-0.023877 -0.025876 -0.058251"
        rpy="0 0 0" />
      <mass
        value="0.57733" />
      <inertia
        ixx="0.0018146"
        ixy="1.867E-05"
        ixz="-0.00034128"
        iyy="0.0019908"
        iyz="2.5832E-05"
        izz="0.00038573" />
    </inertial>
    <visual>
      <origin
        xyz="0 0 0"
        rpy="0 0 0" />
      <geometry>
        <mesh
          filename="package://exo2/meshes/r_leg_hip_r_link.STL" />
      </geometry>
      <material
        name="">
        <color
          rgba="0.79216 0.81961 0.93333 1" />
      </material>
    </visual>
    <collision>
      <origin
        xyz="0 0 0"
        rpy="0 0 0" />
      <geometry>
        <mesh
          filename="package://exo2/meshes/r_leg_hip_r_link.STL" />
      </geometry>
    </collision>
  </link>
  <joint
    name="r_leg_hip_r"
    type="revolute">
    <origin
      xyz="0 0 0"
      rpy="0 0 0" />
    <parent
      link="r_leg_hip_y_link" />
    <child
      link="r_leg_hip_r_link" />
    <axis
      xyz="1 0 0" />
    <limit
      effort="0"
      velocity="0" />
  </joint>
  <link
    name="r_leg_hip_p_link">
    <inertial>
      <origin
        xyz="0.0119162167049423 -0.0160889612900433 -0.159019579168821"
        rpy="0 0 0" />
      <mass
        value="0.286678786770336" />
      <inertia
        ixx="0.00113459314865265"
        ixy="1.62949619200087E-05"
        ixz="8.0589762179723E-05"
        iyy="0.00105887331308655"
        iyz="-0.000191213526187752"
        izz="9.08598704249653E-05" />
    </inertial>
    <visual>
      <origin
        xyz="0 0 0"
        rpy="0 0 0" />
      <geometry>
        <mesh
          filename="package://exo2/meshes/r_leg_hip_p_link.STL" />
      </geometry>
      <material
        name="">
        <color
          rgba="0.792156862745098 0.819607843137255 0.933333333333333 1" />
      </material>
    </visual>
    <collision>
      <origin
        xyz="0 0 0"
        rpy="0 0 0" />
      <geometry>
        <mesh
          filename="package://exo2/meshes/r_leg_hip_p_link.STL" />
      </geometry>
    </collision>
  </link>
  <joint
    name="r_leg_hip_p"
    type="revolute">
    <origin
      xyz="-0.000235 0.0020842 -0.14103"
      rpy="0 0 0" />
    <parent
      link="r_leg_hip_r_link" />
    <child
      link="r_leg_hip_p_link" />
    <axis
      xyz="0 1 0" />
    <limit
      effort="0"
      velocity="0" />
  </joint>
  <link
    name="r_leg_kn_p_link">
    <inertial>
      <origin
        xyz="-0.0252867564411306 0.0309808685867933 -0.129705092898571"
        rpy="0 0 0" />
      <mass
        value="0.501849157200272" />
      <inertia
        ixx="0.000749537517045051"
        ixy="3.60981923292368E-05"
        ixz="-3.22295673042344E-05"
        iyy="0.000965520862241441"
        iyz="0.000150693128088655"
        izz="0.000581130320590493" />
    </inertial>
    <visual>
      <origin
        xyz="0 0 0"
        rpy="0 0 0" />
      <geometry>
        <mesh
          filename="package://exo2/meshes/r_leg_kn_p_link.STL" />
      </geometry>
      <material
        name="">
        <color
          rgba="0.792156862745098 0.819607843137255 0.933333333333333 1" />
      </material>
    </visual>
    <collision>
      <origin
        xyz="0 0 0"
        rpy="0 0 0" />
      <geometry>
        <mesh
          filename="package://exo2/meshes/r_leg_kn_p_link.STL" />
      </geometry>
    </collision>
  </link>
  <joint
    name="r_leg_kn_p"
    type="revolute">
    <origin
      xyz="0.017958 0.0039708 -0.2444"
      rpy="0 0 0" />
    <parent
      link="r_leg_hip_p_link" />
    <child
      link="r_leg_kn_p_link" />
    <axis
      xyz="0 1 0" />
    <limit
      effort="0"
      velocity="0" />
  </joint>
  <link
    name="r_leg_an_p_link">
    <inertial>
      <origin
        xyz="-0.029942 -0.00060381 0.00047371"
        rpy="0 0 0" />
      <mass
        value="0.032575" />
      <inertia
        ixx="4.1822E-06"
        ixy="3.0143E-08"
        ixz="4.2942E-08"
        iyy="2.6397E-06"
        iyz="-6.0941E-08"
        izz="6.8187E-06" />
    </inertial>
    <visual>
      <origin
        xyz="0 0 0"
        rpy="0 0 0" />
      <geometry>
        <mesh
          filename="package://exo2/meshes/r_leg_an_p_link.STL" />
      </geometry>
      <material
        name="">
        <color
          rgba="0.79216 0.81961 0.93333 1" />
      </material>
    </visual>
    <collision>
      <origin
        xyz="0 0 0"
        rpy="0 0 0" />
      <geometry>
        <mesh
          filename="package://exo2/meshes/r_leg_an_p_link.STL" />
      </geometry>
    </collision>
  </link>
  <joint
    name="r_leg_an_p"
    type="revolute">
    <origin
      xyz="0.015862 0.035899 -0.20884"
      rpy="0 0 0" />
    <parent
      link="r_leg_kn_p_link" />
    <child
      link="r_leg_an_p_link" />
    <axis
      xyz="0 1 0" />
    <limit
      effort="0"
      velocity="0" />
  </joint>
  <link
    name="r_leg_an_r_link">
    <inertial>
      <origin
        xyz="0.0358712048271737 0.000136366291676838 -0.0464921621721352"
        rpy="0 0 0" />
      <mass
        value="0.199852749313157" />
      <inertia
        ixx="2.90585598164805E-05"
        ixy="-2.59676895045742E-06"
        ixz="8.99497426057764E-06"
        iyy="6.35160118369035E-05"
        iyz="3.33981797429722E-07"
        izz="6.364590008288E-05" />
    </inertial>
    <visual>
      <origin
        xyz="0 0 0"
        rpy="0 0 0" />
      <geometry>
        <mesh
          filename="package://exo2/meshes/r_leg_an_r_link.STL" />
      </geometry>
      <material
        name="">
        <color
          rgba="0.792156862745098 0.819607843137255 0.933333333333333 1" />
      </material>
    </visual>
    <collision>
      <origin
        xyz="0 0 0"
        rpy="0 0 0" />
      <geometry>
        <mesh
          filename="package://exo2/meshes/r_leg_an_r_link.STL" />
      </geometry>
    </collision>
  </link>
  <joint
    name="r_leg_an_r"
    type="revolute">
    <origin
      xyz="0 0 0"
      rpy="0 0 0" />
    <parent
      link="r_leg_an_p_link" />
    <child
      link="r_leg_an_r_link" />
    <axis
      xyz="1 0 0" />
    <limit
      effort="0"
      velocity="0" />
  </joint>
</robot>