<robot
  name="exo_fri2">
  <link
    name="pelvis_link">
    <inertial>
      <origin
        xyz="-0.0229570391634383 9.79841631490452E-06 -0.0791579286364339"
        rpy="0 0 0" />
      <mass
        value="0.876180506785054" />
      <inertia
        ixx="0.0018274599707449"
        ixy="2.77946712790342E-06"
        ixz="-2.8214836938785E-05"
        iyy="0.000542716087592879"
        iyz="-1.88988098707489E-06"
        izz="0.00181893616699862" />
    </inertial>
    <visual>
      <origin
        xyz="0 0 0"
        rpy="0 0 0" />
      <geometry>
        <mesh
          filename="package://exo_fri2/meshes/pelvis_link.STL" />
      </geometry>
      <material
        name="">
        <color
          rgba="0.792156862745098 0.819607843137255 0.933333333333333 1" />
      </material>
    </visual>
    <collision>
      <origin
        xyz="0 0 0"
        rpy="0 0 0" />
      <geometry>
        <mesh
          filename="package://exo_fri2/meshes/pelvis_link.STL" />
      </geometry>
    </collision>
  </link>
  <link
    name="l_leg_hip_y_link">
    <inertial>
      <origin
        xyz="0.000194866698194046 3.98997327107631E-05 0.00285846754175562"
        rpy="0 0 0" />
      <mass
        value="0.0865282088524624" />
      <inertia
        ixx="1.13911359505298E-06"
        ixy="-1.11411508271771E-10"
        ixz="-2.37226666721844E-08"
        iyy="6.2899579319631E-06"
        iyz="-4.85731050099276E-09"
        izz="5.15088996081038E-06" />
    </inertial>
    <visual>
      <origin
        xyz="0 0 0"
        rpy="0 0 0" />
      <geometry>
        <mesh
          filename="package://exo_fri2/meshes/l_leg_hip_y_link.STL" />
      </geometry>
      <material
        name="">
        <color
          rgba="0.792156862745098 0.819607843137255 0.933333333333333 1" />
      </material>
    </visual>
    <collision>
      <origin
        xyz="0 0 0"
        rpy="0 0 0" />
      <geometry>
        <mesh
          filename="package://exo_fri2/meshes/l_leg_hip_y_link.STL" />
      </geometry>
    </collision>
  </link>
  <joint
    name="l_leg_hip_y"
    type="revolute">
    <origin
      xyz="0.023 0.125 -0.0813"
      rpy="0 0 0" />
    <parent
      link="pelvis_link" />
    <child
      link="l_leg_hip_y_link" />
    <axis
      xyz="0 0 1" />
    <limit 
      velocity="6.5" 
      effort="1000" 
      lower="-2.826" 
      upper="2.826" />
    <dynamics 
      damping="0.9" 
      friction="0.0" />
  </joint> 
<xacro:insert_transmission name="l_leg_hip_y" />
  <link
    name="l_leg_hip_r_link">
    <inertial>
      <origin
        xyz="-0.0228672177413694 0.0267340296554695 -0.057861572875431"
        rpy="0 0 0" />
      <mass
        value="0.577322605082582" />
      <inertia
        ixx="0.00181457155966255"
        ixy="-1.38251521700881E-05"
        ixz="-0.000341824932119138"
        iyy="0.00199152298330253"
        iyz="-2.11084833211533E-06"
        izz="0.000385594954323664" />
    </inertial>
    <visual>
      <origin
        xyz="0 0 0"
        rpy="0 0 0" />
      <geometry>
        <mesh
          filename="package://exo_fri2/meshes/l_leg_hip_r_link.STL" />
      </geometry>
      <material
        name="">
        <color
          rgba="0.792156862745098 0.819607843137255 0.933333333333333 1" />
      </material>
    </visual>
    <collision>
      <origin
        xyz="0 0 0"
        rpy="0 0 0" />
      <geometry>
        <mesh
          filename="package://exo_fri2/meshes/l_leg_hip_r_link.STL" />
      </geometry>
    </collision>
  </link>
  <joint
    name="l_leg_hip_r"
    type="revolute">
    <origin
      xyz="0 0 0"
      rpy="0 0 0" />
    <parent
      link="l_leg_hip_y_link" />
    <child
      link="l_leg_hip_r_link" />
    <axis
      xyz="1 0 0" />
    <limit 
      velocity="6.5" 
      effort="1000" 
      lower="-2.826" 
      upper="2.826" />
    <dynamics 
      damping="0.9" 
      friction="0.0" />
  </joint> 
<xacro:insert_transmission name="l_leg_hip_r" />
  <link
    name="l_leg_hip_p_link">
    <inertial>
      <origin
        xyz="-0.000116198463840173 0.0284688740026196 -0.159183589997654"
        rpy="0 0 0" />
      <mass
        value="0.286678540994592" />
      <inertia
        ixx="0.00114218481999952"
        ixy="-6.6656854843246E-07"
        ixz="-4.17701505256595E-07"
        iyy="0.00105234709309922"
        iyz="0.000208313575818116"
        izz="9.25186266106955E-05" />
    </inertial>
    <visual>
      <origin
        xyz="0 0 0"
        rpy="0 0 0" />
      <geometry>
        <mesh
          filename="package://exo_fri2/meshes/l_leg_hip_p_link.STL" />
      </geometry>
      <material
        name="">
        <color
          rgba="0.792156862745098 0.819607843137255 0.933333333333333 1" />
      </material>
    </visual>
    <collision>
      <origin
        xyz="0 0 0"
        rpy="0 0 0" />
      <geometry>
        <mesh
          filename="package://exo_fri2/meshes/l_leg_hip_p_link.STL" />
      </geometry>
    </collision>
  </link>
  <joint
    name="l_leg_hip_p"
    type="revolute">
    <origin
      xyz="0.000765 -0.0097362 -0.14104"
      rpy="0 0 0" />
    <parent
      link="l_leg_hip_r_link" />
    <child
      link="l_leg_hip_p_link" />
    <axis
      xyz="0 1 0" />
    <limit 
      velocity="6.5" 
      effort="1000" 
      lower="-2.826" 
      upper="2.826" />
    <dynamics 
      damping="0.9" 
      friction="0.0" />
  </joint> 
<xacro:insert_transmission name="l_leg_hip_p" />
  <link
    name="l_leg_kn_p_link">
    <inertial>
      <origin
        xyz="-0.0348628624504665 -0.0190683597425377 -0.127805036988548"
        rpy="0 0 0" />
      <mass
        value="0.501847265279983" />
      <inertia
        ixx="0.000745259566339444"
        ixy="-5.13138154637278E-05"
        ixz="-4.31450822433219E-05"
        iyy="0.000968498963909832"
        iyz="-0.000141965074802525"
        izz="0.000582611386949195" />
    </inertial>
    <visual>
      <origin
        xyz="0 0 0"
        rpy="0 0 0" />
      <geometry>
        <mesh
          filename="package://exo_fri2/meshes/l_leg_kn_p_link.STL" />
      </geometry>
      <material
        name="">
        <color
          rgba="0.792156862745098 0.819607843137255 0.933333333333333 1" />
      </material>
    </visual>
    <collision>
      <origin
        xyz="0 0 0"
        rpy="0 0 0" />
      <geometry>
        <mesh
          filename="package://exo_fri2/meshes/l_leg_kn_p_link.STL" />
      </geometry>
    </collision>
  </link>
  <joint
    name="l_leg_kn_p"
    type="revolute">
    <origin
      xyz="0 -0.00025 -0.2451"
      rpy="0 0 0" />
    <parent
      link="l_leg_hip_p_link" />
    <child
      link="l_leg_kn_p_link" />
    <axis
      xyz="0 1 0" />
    <limit 
      velocity="6.5" 
      effort="1000" 
      lower="-2.826" 
      upper="2.826" />
    <dynamics 
      damping="0.9" 
      friction="0.0" />
  </joint> 
<xacro:insert_transmission name="l_leg_kn_p" />
  <link
    name="l_leg_an_p_link">
    <inertial>
      <origin
        xyz="-0.0299520881007188 2.09226775349514E-08 3.0086740876456E-09"
        rpy="0 0 0" />
      <mass
        value="0.0325752774497041" />
      <inertia
        ixx="4.18208814046054E-06"
        ixy="1.56710141350867E-12"
        ixz="2.25348451477354E-13"
        iyy="2.63816527708645E-06"
        iyz="-2.79139167451849E-19"
        izz="6.82025341754691E-06" />
    </inertial>
    <visual>
      <origin
        xyz="0 0 0"
        rpy="0 0 0" />
      <geometry>
        <mesh
          filename="package://exo_fri2/meshes/l_leg_an_p_link.STL" />
      </geometry>
      <material
        name="">
        <color
          rgba="0.792156862745098 0.819607843137255 0.933333333333333 1" />
      </material>
    </visual>
    <collision>
      <origin
        xyz="0 0 0"
        rpy="0 0 0" />
      <geometry>
        <mesh
          filename="package://exo_fri2/meshes/l_leg_an_p_link.STL" />
      </geometry>
    </collision>
  </link>
  <joint
    name="l_leg_an_p"
    type="revolute">
    <origin
      xyz="0 -0.022 -0.21"
      rpy="0 0 0" />
    <parent
      link="l_leg_kn_p_link" />
    <child
      link="l_leg_an_p_link" />
    <axis
      xyz="0 1 0" />
    <limit 
      velocity="6.5" 
      effort="1000" 
      lower="-2.826" 
      upper="2.826" />
    <dynamics 
      damping="0.9" 
      friction="0.0" />
  </joint> 
<xacro:insert_transmission name="l_leg_an_p" />
  <link
    name="l_leg_an_r_link">
    <inertial>
      <origin
        xyz="0.0362143728561817 0.00041776190047349 -0.0460605874777161"
        rpy="0 0 0" />
      <mass
        value="2.0447635642258" />
      <inertia
        ixx="2.92766891537317E-05"
        ixy="2.23425331154983E-06"
        ixz="7.29798818128467E-06"
        iyy="7.35944581513633E-05"
        iyz="-1.46086744570418E-07"
        izz="7.40029664850696E-05" />
    </inertial>
    <visual>
      <origin
        xyz="0 0 0"
        rpy="0 0 0" />
      <geometry>
        <mesh
          filename="package://exo_fri2/meshes/l_leg_an_r_link.STL" />
      </geometry>
      <material
        name="">
        <color
          rgba="0.792156862745098 0.819607843137255 0.933333333333333 1" />
      </material>
    </visual>
    <collision>
      <origin
        xyz="0 0 0"
        rpy="0 0 0" />
      <geometry>
        <mesh
          filename="package://exo_fri2/meshes/l_leg_an_r_link.STL" />
      </geometry>
    </collision>
  </link>
  <joint
    name="l_leg_an_r"
    type="revolute">
    <origin
      xyz="0 0 0"
      rpy="0 0 0" />
    <parent
      link="l_leg_an_p_link" />
    <child
      link="l_leg_an_r_link" />
    <axis
      xyz="1 0 0" />
    <limit 
      velocity="6.5" 
      effort="1000" 
      lower="-2.826" 
      upper="2.826" />
    <dynamics 
      damping="0.9" 
      friction="0.0" />
  </joint> 
<xacro:insert_transmission name="l_leg_an_r" />
  <link
    name="r_leg_hip_y_link">
    <inertial>
      <origin
        xyz="0.000194859448184315 -3.99012608066768E-05 0.00285850027010753"
        rpy="0 0 0" />
      <mass
        value="0.0865285731833129" />
      <inertia
        ixx="1.13912084419969E-06"
        ixy="1.11411552257724E-10"
        ixz="-2.37218589140582E-08"
        iyy="6.2899651385115E-06"
        iyz="4.8575118536712E-09"
        izz="5.15088992167497E-06" />
    </inertial>
    <visual>
      <origin
        xyz="0 0 0"
        rpy="0 0 0" />
      <geometry>
        <mesh
          filename="package://exo_fri2/meshes/r_leg_hip_y_link.STL" />
      </geometry>
      <material
        name="">
        <color
          rgba="0.792156862745098 0.819607843137255 0.933333333333333 1" />
      </material>
    </visual>
    <collision>
      <origin
        xyz="0 0 0"
        rpy="0 0 0" />
      <geometry>
        <mesh
          filename="package://exo_fri2/meshes/r_leg_hip_y_link.STL" />
      </geometry>
    </collision>
  </link>
  <joint
    name="r_leg_hip_y"
    type="revolute">
    <origin
      xyz="0.023 -0.125 -0.0813"
      rpy="0 0 0" />
    <parent
      link="pelvis_link" />
    <child
      link="r_leg_hip_y_link" />
    <axis
      xyz="0 0 1" />
    <limit 
      velocity="6.5" 
      effort="1000" 
      lower="-2.826" 
      upper="2.826" />
    <dynamics 
      damping="0.9" 
      friction="0.0" />
  </joint> 
<xacro:insert_transmission name="r_leg_hip_y" />
  <link
    name="r_leg_hip_r_link">
    <inertial>
      <origin
        xyz="-0.023877009103276 -0.0267341360094503 -0.0578620358278071"
        rpy="0 0 0" />
      <mass
        value="0.577327897793504" />
      <inertia
        ixx="0.00181455865797064"
        ixy="1.3624437201598E-05"
        ixz="-0.00034151634759538"
        iyy="0.00199123255685572"
        iyz="2.10370363346488E-06"
        izz="0.000385318948306946" />
    </inertial>
    <visual>
      <origin
        xyz="0 0 0"
        rpy="0 0 0" />
      <geometry>
        <mesh
          filename="package://exo_fri2/meshes/r_leg_hip_r_link.STL" />
      </geometry>
      <material
        name="">
        <color
          rgba="0.792156862745098 0.819607843137255 0.933333333333333 1" />
      </material>
    </visual>
    <collision>
      <origin
        xyz="0 0 0"
        rpy="0 0 0" />
      <geometry>
        <mesh
          filename="package://exo_fri2/meshes/r_leg_hip_r_link.STL" />
      </geometry>
    </collision>
  </link>
  <joint
    name="r_leg_hip_r"
    type="revolute">
    <origin
      xyz="0 0 0"
      rpy="0 0 0" />
    <parent
      link="r_leg_hip_y_link" />
    <child
      link="r_leg_hip_r_link" />
    <axis
      xyz="1 0 0" />
    <limit 
      velocity="6.5" 
      effort="1000" 
      lower="-2.826" 
      upper="2.826" />
    <dynamics 
      damping="0.9" 
      friction="0.0" />
  </joint> 
<xacro:insert_transmission name="r_leg_hip_r" />
  <link
    name="r_leg_hip_p_link">
    <inertial>
      <origin
        xyz="-0.000119608407726818 -0.0284075969398045 -0.159183646260211"
        rpy="0 0 0" />
      <mass
        value="0.286679006041324" />
      <inertia
        ixx="0.00114082497447434"
        ixy="6.32801216900449E-07"
        ixz="-4.92592484266524E-07"
        iyy="0.00105234766959689"
        iyz="-0.000207601330706595"
        izz="9.11579594381596E-05" />
    </inertial>
    <visual>
      <origin
        xyz="0 0 0"
        rpy="0 0 0" />
      <geometry>
        <mesh
          filename="package://exo_fri2/meshes/r_leg_hip_p_link.STL" />
      </geometry>
      <material
        name="">
        <color
          rgba="0.792156862745098 0.819607843137255 0.933333333333333 1" />
      </material>
    </visual>
    <collision>
      <origin
        xyz="0 0 0"
        rpy="0 0 0" />
      <geometry>
        <mesh
          filename="package://exo_fri2/meshes/r_leg_hip_p_link.STL" />
      </geometry>
    </collision>
  </link>
  <joint
    name="r_leg_hip_p"
    type="revolute">
    <origin
      xyz="-0.000235 0.0097362 -0.14104"
      rpy="0 0 0" />
    <parent
      link="r_leg_hip_r_link" />
    <child
      link="r_leg_hip_p_link" />
    <axis
      xyz="0 1 0" />
    <limit 
      velocity="6.5" 
      effort="1000" 
      lower="-2.826" 
      upper="2.826" />
    <dynamics 
      damping="0.9" 
      friction="0.0" />
  </joint> 
<xacro:insert_transmission name="r_leg_hip_p" />
  <link
    name="r_leg_kn_p_link">
    <inertial>
      <origin
        xyz="-0.0348599742971025 0.0190722316896734 -0.127803416335954"
        rpy="0 0 0" />
      <mass
        value="0.501848142816981" />
      <inertia
        ixx="0.000745283229708751"
        ixy="5.13026291501537E-05"
        ixz="-4.31583183152432E-05"
        iyy="0.000968382519973806"
        iyz="0.000141975658542831"
        izz="0.00058251910660915" />
    </inertial>
    <visual>
      <origin
        xyz="0 0 0"
        rpy="0 0 0" />
      <geometry>
        <mesh
          filename="package://exo_fri2/meshes/r_leg_kn_p_link.STL" />
      </geometry>
      <material
        name="">
        <color
          rgba="0.792156862745098 0.819607843137255 0.933333333333333 1" />
      </material>
    </visual>
    <collision>
      <origin
        xyz="0 0 0"
        rpy="0 0 0" />
      <geometry>
        <mesh
          filename="package://exo_fri2/meshes/r_leg_kn_p_link.STL" />
      </geometry>
    </collision>
  </link>
  <joint
    name="r_leg_kn_p"
    type="revolute">
    <origin
      xyz="0 0.00075 -0.2451"
      rpy="0 0 0" />
    <parent
      link="r_leg_hip_p_link" />
    <child
      link="r_leg_kn_p_link" />
    <axis
      xyz="0 1 0" />
    <limit 
      velocity="6.5" 
      effort="1000" 
      lower="-2.826" 
      upper="2.826" />
    <dynamics 
      damping="0.9" 
      friction="0.0" />
  </joint> 
<xacro:insert_transmission name="r_leg_kn_p" />
  <link
    name="r_leg_an_p_link">
    <inertial>
      <origin
        xyz="-0.0299520881006903 2.09226773250498E-08 3.00867425417906E-09"
        rpy="0 0 0" />
      <mass
        value="0.0325752774497039" />
      <inertia
        ixx="4.18208814046053E-06"
        ixy="1.5670981579651E-12"
        ixz="2.2534842189336E-13"
        iyy="2.63816527708159E-06"
        iyz="-2.29567390544923E-19"
        izz="6.82025341754205E-06" />
    </inertial>
    <visual>
      <origin
        xyz="0 0 0"
        rpy="0 0 0" />
      <geometry>
        <mesh
          filename="package://exo_fri2/meshes/r_leg_an_p_link.STL" />
      </geometry>
      <material
        name="">
        <color
          rgba="0.792156862745098 0.819607843137255 0.933333333333333 1" />
      </material>
    </visual>
    <collision>
      <origin
        xyz="0 0 0"
        rpy="0 0 0" />
      <geometry>
        <mesh
          filename="package://exo_fri2/meshes/r_leg_an_p_link.STL" />
      </geometry>
    </collision>
  </link>
  <joint
    name="r_leg_an_p"
    type="revolute">
    <origin
      xyz="0 0.022 -0.21"
      rpy="0 0 0" />
    <parent
      link="r_leg_kn_p_link" />
    <child
      link="r_leg_an_p_link" />
    <axis
      xyz="0 1 0" />
    <limit 
      velocity="6.5" 
      effort="1000" 
      lower="-2.826" 
      upper="2.826" />
    <dynamics 
      damping="0.9" 
      friction="0.0" />
  </joint> 
<xacro:insert_transmission name="r_leg_an_p" />
  <link
    name="r_leg_an_r_link">
    <inertial>
      <origin
        xyz="0.0365974815210963 -0.00127278229934455 -0.0459051713323503"
        rpy="0 0 0" />
      <mass
        value="1.99852541528706" />
      <inertia
        ixx="2.86919257638339E-05"
        ixy="-1.77579615167557E-06"
        ixz="8.47452589586996E-06"
        iyy="6.36105474883179E-05"
        iyz="1.27098628999202E-07"
        izz="6.39182398896403E-05" />
    </inertial>
    <visual>
      <origin
        xyz="0 0 0"
        rpy="0 0 0" />
      <geometry>
        <mesh
          filename="package://exo_fri2/meshes/r_leg_an_r_link.STL" />
      </geometry>
      <material
        name="">
        <color
          rgba="0.792156862745098 0.819607843137255 0.933333333333333 1" />
      </material>
    </visual>
    <collision>
      <origin
        xyz="0 0 0"
        rpy="0 0 0" />
      <geometry>
        <mesh
          filename="package://exo_fri2/meshes/r_leg_an_r_link.STL" />
      </geometry>
    </collision>
  </link>
  <joint
    name="r_leg_an_r"
    type="revolute">
    <origin
      xyz="0 0 0"
      rpy="0 0 0" />
    <parent
      link="r_leg_an_p_link" />
    <child
      link="r_leg_an_r_link" />
    <axis
      xyz="1 0 0" />
    <limit 
      velocity="6.5" 
      effort="1000" 
      lower="-2.826" 
      upper="2.826" />
    <dynamics 
      damping="0.9" 
      friction="0.0" />
  </joint> 
<xacro:insert_transmission name="r_leg_an_r" />
</robot>